Workbook
Name Slicer_Quarter: #N/A

Sheet Source Data
A1: Month | B1: Revenue | C1: Expenses | D1: Leads | E1: Orders | F1: Month Num | G1: Quarter
A2: Jan | B2: 120000 | C2: 80000 | D2: 450 | E2: 90 | F2: =MATCH(A2,{"Jan","Feb","Mar","Apr","May","Jun","Jul","Aug","Sep","Oct","Nov","Dec"},0) | G2: ="Q"&ROUNDUP(MATCH(A2,{"Jan","Feb","Mar","Apr","May","Jun","Jul","Aug","Sep","Oct","Nov","Dec"},0)/3,0)
A3: Feb | B3: 135000 | C3: 85000 | D3: 500 | E3: 100 | F3: =MATCH(A3,{"Jan","Feb","Mar","Apr","May","Jun","Jul","Aug","Sep","Oct","Nov","Dec"},0) | G3: ="Q"&ROUNDUP(MATCH(A3,{"Jan","Feb","Mar","Apr","May","Jun","Jul","Aug","Sep","Oct","Nov","Dec"},0)/3,0)
A4: Mar | B4: 128000 | C4: 82000 | D4: 470 | E4: 95 | F4: =MATCH(A4,{"Jan","Feb","Mar","Apr","May","Jun","Jul","Aug","Sep","Oct","Nov","Dec"},0) | G4: ="Q"&ROUNDUP(MATCH(A4,{"Jan","Feb","Mar","Apr","May","Jun","Jul","Aug","Sep","Oct","Nov","Dec"},0)/3,0)
A5: Apr | B5: 150000 | C5: 90000 | D5: 560 | E5: 110 | F5: =MATCH(A5,{"Jan","Feb","Mar","Apr","May","Jun","Jul","Aug","Sep","Oct","Nov","Dec"},0) | G5: ="Q"&ROUNDUP(MATCH(A5,{"Jan","Feb","Mar","Apr","May","Jun","Jul","Aug","Sep","Oct","Nov","Dec"},0)/3,0)
A6: May | B6: 165000 | C6: 98000 | D6: 620 | E6: 125 | F6: =MATCH(A6,{"Jan","Feb","Mar","Apr","May","Jun","Jul","Aug","Sep","Oct","Nov","Dec"},0) | G6: ="Q"&ROUNDUP(MATCH(A6,{"Jan","Feb","Mar","Apr","May","Jun","Jul","Aug","Sep","Oct","Nov","Dec"},0)/3,0)
A7: Jun | B7: 172000 | C7: 102000 | D7: 650 | E7: 130 | F7: =MATCH(A7,{"Jan","Feb","Mar","Apr","May","Jun","Jul","Aug","Sep","Oct","Nov","Dec"},0) | G7: ="Q"&ROUNDUP(MATCH(A7,{"Jan","Feb","Mar","Apr","May","Jun","Jul","Aug","Sep","Oct","Nov","Dec"},0)/3,0)
A8: Jul | B8: 180000 | C8: 108000 | D8: 690 | E8: 138 | F8: =MATCH(A8,{"Jan","Feb","Mar","Apr","May","Jun","Jul","Aug","Sep","Oct","Nov","Dec"},0) | G8: ="Q"&ROUNDUP(MATCH(A8,{"Jan","Feb","Mar","Apr","May","Jun","Jul","Aug","Sep","Oct","Nov","Dec"},0)/3,0)
A9: Aug | B9: 176000 | C9: 105000 | D9: 670 | E9: 134 | F9: =MATCH(A9,{"Jan","Feb","Mar","Apr","May","Jun","Jul","Aug","Sep","Oct","Nov","Dec"},0) | G9: ="Q"&ROUNDUP(MATCH(A9,{"Jan","Feb","Mar","Apr","May","Jun","Jul","Aug","Sep","Oct","Nov","Dec"},0)/3,0)
A10: Sep | B10: 190000 | C10: 112000 | D10: 720 | E10: 145 | F10: =MATCH(A10,{"Jan","Feb","Mar","Apr","May","Jun","Jul","Aug","Sep","Oct","Nov","Dec"},0) | G10: ="Q"&ROUNDUP(MATCH(A10,{"Jan","Feb","Mar","Apr","May","Jun","Jul","Aug","Sep","Oct","Nov","Dec"},0)/3,0)
A11: Oct | B11: 205000 | C11: 118000 | D11: 780 | E11: 158 | F11: =MATCH(A11,{"Jan","Feb","Mar","Apr","May","Jun","Jul","Aug","Sep","Oct","Nov","Dec"},0) | G11: ="Q"&ROUNDUP(MATCH(A11,{"Jan","Feb","Mar","Apr","May","Jun","Jul","Aug","Sep","Oct","Nov","Dec"},0)/3,0)
A12: Nov | B12: 218000 | C12: 125000 | D12: 820 | E12: 165 | F12: =MATCH(A12,{"Jan","Feb","Mar","Apr","May","Jun","Jul","Aug","Sep","Oct","Nov","Dec"},0) | G12: ="Q"&ROUNDUP(MATCH(A12,{"Jan","Feb","Mar","Apr","May","Jun","Jul","Aug","Sep","Oct","Nov","Dec"},0)/3,0)
A13: Dec | B13: 240000 | C13: 138000 | D13: 900 | E13: 182 | F13: =MATCH(A13,{"Jan","Feb","Mar","Apr","May","Jun","Jul","Aug","Sep","Oct","Nov","Dec"},0) | G13: ="Q"&ROUNDUP(MATCH(A13,{"Jan","Feb","Mar","Apr","May","Jun","Jul","Aug","Sep","Oct","Nov","Dec"},0)/3,0)

Sheet Calculations
A1: Month | B1: Revenue | C1: Expenses | D1: Profit | E1: Leads | F1: Orders | G1: Profit Margin % | H1: Monthly Growth %
A2: ='Source Data'!A2 | B2: ='Source Data'!B2 | C2: ='Source Data'!C2 | D2: =B2-C2 | E2: ='Source Data'!D2 | F2: ='Source Data'!E2 | G2: =IF(B2=0,"",D2/B2) | H2: ""
A3: ='Source Data'!A3 | B3: ='Source Data'!B3 | C3: ='Source Data'!C3 | D3: =B3-C3 | E3: ='Source Data'!D3 | F3: ='Source Data'!E3 | G3: =IF(B3=0,"",D3/B3) | H3: =IF(B2=0,"",(B3-B2)/B2)
A4: ='Source Data'!A4 | B4: ='Source Data'!B4 | C4: ='Source Data'!C4 | D4: =B4-C4 | E4: ='Source Data'!D4 | F4: ='Source Data'!E4 | G4: =IF(B4=0,"",D4/B4) | H4: =IF(B3=0,"",(B4-B3)/B3)
A5: ='Source Data'!A5 | B5: ='Source Data'!B5 | C5: ='Source Data'!C5 | D5: =B5-C5 | E5: ='Source Data'!D5 | F5: ='Source Data'!E5 | G5: =IF(B5=0,"",D5/B5) | H5: =IF(B4=0,"",(B5-B4)/B4)
A6: ='Source Data'!A6 | B6: ='Source Data'!B6 | C6: ='Source Data'!C6 | D6: =B6-C6 | E6: ='Source Data'!D6 | F6: ='Source Data'!E6 | G6: =IF(B6=0,"",D6/B6) | H6: =IF(B5=0,"",(B6-B5)/B5)
A7: ='Source Data'!A7 | B7: ='Source Data'!B7 | C7: ='Source Data'!C7 | D7: =B7-C7 | E7: ='Source Data'!D7 | F7: ='Source Data'!E7 | G7: =IF(B7=0,"",D7/B7) | H7: =IF(B6=0,"",(B7-B6)/B6)
A8: ='Source Data'!A8 | B8: ='Source Data'!B8 | C8: ='Source Data'!C8 | D8: =B8-C8 | E8: ='Source Data'!D8 | F8: ='Source Data'!E8 | G8: =IF(B8=0,"",D8/B8) | H8: =IF(B7=0,"",(B8-B7)/B7)
A9: ='Source Data'!A9 | B9: ='Source Data'!B9 | C9: ='Source Data'!C9 | D9: =B9-C9 | E9: ='Source Data'!D9 | F9: ='Source Data'!E9 | G9: =IF(B9=0,"",D9/B9) | H9: =IF(B8=0,"",(B9-B8)/B8)
A10: ='Source Data'!A10 | B10: ='Source Data'!B10 | C10: ='Source Data'!C10 | D10: =B10-C10 | E10: ='Source Data'!D10 | F10: ='Source Data'!E10 | G10: =IF(B10=0,"",D10/B10) | H10: =IF(B9=0,"",(B10-B9)/B9)
A11: ='Source Data'!A11 | B11: ='Source Data'!B11 | C11: ='Source Data'!C11 | D11: =B11-C11 | E11: ='Source Data'!D11 | F11: ='Source Data'!E11 | G11: =IF(B11=0,"",D11/B11) | H11: =IF(B10=0,"",(B11-B10)/B10)
A12: ='Source Data'!A12 | B12: ='Source Data'!B12 | C12: ='Source Data'!C12 | D12: =B12-C12 | E12: ='Source Data'!D12 | F12: ='Source Data'!E12 | G12: =IF(B12=0,"",D12/B12) | H12: =IF(B11=0,"",(B12-B11)/B11)
A13: ='Source Data'!A13 | B13: ='Source Data'!B13 | C13: ='Source Data'!C13 | D13: =B13-C13 | E13: ='Source Data'!D13 | F13: ='Source Data'!E13 | G13: =IF(B13=0,"",D13/B13) | H13: =IF(B12=0,"",(B13-B12)/B12)
A14: TOTAL | B14: =SUM(B2:B13) | C14: =SUM(C2:C13) | D14: =SUM(D2:D13) | E14: =SUM(E2:E13) | F14: =SUM(F2:F13) | G14: =IF(B14=0,"",D14/B14) | H14: ""

Sheet Charts
A1: Revenue Trend Data
A2: Month | B2: Revenue
A3: ='Source Data'!A2 | B3: ='Source Data'!B2
A4: ='Source Data'!A3 | B4: ='Source Data'!B3
A5: ='Source Data'!A4 | B5: ='Source Data'!B4
A6: ='Source Data'!A5 | B6: ='Source Data'!B5
A7: ='Source Data'!A6 | B7: ='Source Data'!B6
A8: ='Source Data'!A7 | B8: ='Source Data'!B7
A9: ='Source Data'!A8 | B9: ='Source Data'!B8
A10: ='Source Data'!A9 | B10: ='Source Data'!B9
A11: ='Source Data'!A10 | B11: ='Source Data'!B10
A12: ='Source Data'!A11 | B12: ='Source Data'!B11
A13: ='Source Data'!A12 | B13: ='Source Data'!B12
A14: ='Source Data'!A13 | B14: ='Source Data'!B13
A16: Revenue vs Expenses Data
A17: Month | B17: Revenue | C17: Expenses
A18: ='Source Data'!A2 | B18: ='Source Data'!B2 | C18: ='Source Data'!C2
A19: ='Source Data'!A3 | B19: ='Source Data'!B3 | C19: ='Source Data'!C3
A20: ='Source Data'!A4 | B20: ='Source Data'!B4 | C20: ='Source Data'!C4
A21: ='Source Data'!A5 | B21: ='Source Data'!B5 | C21: ='Source Data'!C5
A22: ='Source Data'!A6 | B22: ='Source Data'!B6 | C22: ='Source Data'!C6
A23: ='Source Data'!A7 | B23: ='Source Data'!B7 | C23: ='Source Data'!C7
A24: ='Source Data'!A8 | B24: ='Source Data'!B8 | C24: ='Source Data'!C8
A25: ='Source Data'!A9 | B25: ='Source Data'!B9 | C25: ='Source Data'!C9
A26: ='Source Data'!A10 | B26: ='Source Data'!B10 | C26: ='Source Data'!C10
A27: ='Source Data'!A11 | B27: ='Source Data'!B11 | C27: ='Source Data'!C11
A28: ='Source Data'!A12 | B28: ='Source Data'!B12 | C28: ='Source Data'!C12
A29: ='Source Data'!A13 | B29: ='Source Data'!B13 | C29: ='Source Data'!C13
A31: Month | B31: Revenue | C31: Profit Margin %
A32: ='Source Data'!A2 | B32: ='Source Data'!B2 | C32: =Calculations!G2
A33: ='Source Data'!A3 | B33: ='Source Data'!B3 | C33: =Calculations!G3
A34: ='Source Data'!A4 | B34: ='Source Data'!B4 | C34: =Calculations!G4
A35: ='Source Data'!A5 | B35: ='Source Data'!B5 | C35: =Calculations!G5
A36: ='Source Data'!A6 | B36: ='Source Data'!B6 | C36: =Calculations!G6
A37: ='Source Data'!A7 | B37: ='Source Data'!B7 | C37: =Calculations!G7
A38: ='Source Data'!A8 | B38: ='Source Data'!B8 | C38: =Calculations!G8
A39: ='Source Data'!A9 | B39: ='Source Data'!B9 | C39: =Calculations!G9
A40: ='Source Data'!A10 | B40: ='Source Data'!B10 | C40: =Calculations!G10
A41: ='Source Data'!A11 | B41: ='Source Data'!B11 | C41: =Calculations!G11
A42: ='Source Data'!A12 | B42: ='Source Data'!B12 | C42: =Calculations!G12
...

Sheet Dashboard
B2: ="SALES PERFORMANCE DASHBOARD â€” Profit Margin: "&TEXT(Calculations!G14,"0.0%")
B3: TOTAL REVENUE | D3: TOTAL EXPENSES | F3: TOTAL PROFIT | H3: TOTAL LEADS | J3: TOTAL ORDERS
B4: =Calculations!B14 | D4: =Calculations!C14 | F4: =Calculations!D14 | H4: =Calculations!E14 | J4: =Calculations!F14
B6: ="Profit Margin: "&TEXT(Calculations!G14,"0.0%") | D6: ="Avg Monthly Growth: "&TEXT(AVERAGE(Calculations!H2:H13),"0.0%")

Sheet Forecast
A1: Revenue Forecast — Next 3 Months
A3: Historical Data
A4: Period | B4: Month | C4: Revenue (Actual) | D4: Forecast Revenue | E4: Confidence Interval (±) | F4: Lower Bound | G4: Upper Bound
A5: 1 | B5: Jan | C5: ='Source Data'!B2 | D5: =C5
A6: 2 | B6: Feb | C6: ='Source Data'!B3 | D6: =C6
A7: 3 | B7: Mar | C7: ='Source Data'!B4 | D7: =C7
A8: 4 | B8: Apr | C8: ='Source Data'!B5 | D8: =C8
A9: 5 | B9: May | C9: ='Source Data'!B6 | D9: =C9
A10: 6 | B10: Jun | C10: ='Source Data'!B7 | D10: =C10
A11: 7 | B11: Jul | C11: ='Source Data'!B8 | D11: =C11
A12: 8 | B12: Aug | C12: ='Source Data'!B9 | D12: =C12
A13: 9 | B13: Sep | C13: ='Source Data'!B10 | D13: =C13
A14: 10 | B14: Oct | C14: ='Source Data'!B11 | D14: =C14
A15: 11 | B15: Nov | C15: ='Source Data'!B12 | D15: =C15
A16: 12 | B16: Dec | C16: ='Source Data'!B13 | D16: =C16
A18: Forecast Period (Next Quarter)
A19: Period | B19: Month | C19: Revenue (Actual) | D19: Forecast Revenue | E19: Confidence Interval (±) | F19: Lower Bound | G19: Upper Bound
A20: 13 | B20: Jan (Forecast) | D20: =_xlfn.FORECAST.ETS(A20, $C$5:$C$16, $A$5:$A$16, 1, 1, 1) | E20: =_xlfn.FORECAST.ETS.CONFINT(A20, $C$5:$C$16, $A$5:$A$16, 0.9, 1) | F20: =D20-E20 | G20: =D20+E20
A21: 14 | B21: Feb (Forecast) | D21: =_xlfn.FORECAST.ETS(A21, $C$5:$C$16, $A$5:$A$16, 1, 1, 1) | E21: =_xlfn.FORECAST.ETS.CONFINT(A21, $C$5:$C$16, $A$5:$A$16, 0.9, 1) | F21: =D21-E21 | G21: =D21+E21
A22: 15 | B22: Mar (Forecast) | D22: =_xlfn.FORECAST.ETS(A22, $C$5:$C$16, $A$5:$A$16, 1, 1, 1) | E22: =_xlfn.FORECAST.ETS.CONFINT(A22, $C$5:$C$16, $A$5:$A$16, 0.9, 1) | F22: =D22-E22 | G22: =D22+E22
A24: Summary
A25: Total Historical Revenue | B25: =SUM(C5:C16)
A26: Avg Monthly Revenue | B26: =AVERAGE(C5:C16)
A27: Projected Q1 Revenue | B27: =SUM(D20:D22)
A28: Projected Q1 Lower Bound | B28: =SUM(F20:F22)
A29: Projected Q1 Upper Bound | B29: =SUM(G20:G22)

Sheet What-If
A1: What-If Analysis — Revenue Projection
A3: Scenario Inputs
A5: Projected Monthly Growth Rate: | B5: 0.05 | C5: Type a percentage (e.g. 5%)
A6: Quick Presets: | C6: Select a preset above, then copy it to B5
A8: Tip: | B8: Change the value in B5 — the table and chart below update instantly.
A10: Revenue Projection — Next 12 Months
A11: Month | B11: Starting Revenue | C11: Projected Revenue | D11: Growth Amount
A12: Jan | B12: ='Source Data'!B13 | C12: =IF($B$5<>"",B12*(1+$B$5),"") | D12: =IF(C12="","",C12-B12)
A13: Feb | B13: =IF($B$5<>"",C12,"") | C13: =IF($B$5<>"",B13*(1+$B$5),"") | D13: =IF(C13="","",C13-B13)
A14: Mar | B14: =IF($B$5<>"",C13,"") | C14: =IF($B$5<>"",B14*(1+$B$5),"") | D14: =IF(C14="","",C14-B14)
A15: Apr | B15: =IF($B$5<>"",C14,"") | C15: =IF($B$5<>"",B15*(1+$B$5),"") | D15: =IF(C15="","",C15-B15)
A16: May | B16: =IF($B$5<>"",C15,"") | C16: =IF($B$5<>"",B16*(1+$B$5),"") | D16: =IF(C16="","",C16-B16)
A17: Jun | B17: =IF($B$5<>"",C16,"") | C17: =IF($B$5<>"",B17*(1+$B$5),"") | D17: =IF(C17="","",C17-B17)
A18: Jul | B18: =IF($B$5<>"",C17,"") | C18: =IF($B$5<>"",B18*(1+$B$5),"") | D18: =IF(C18="","",C18-B18)
A19: Aug | B19: =IF($B$5<>"",C18,"") | C19: =IF($B$5<>"",B19*(1+$B$5),"") | D19: =IF(C19="","",C19-B19)
A20: Sep | B20: =IF($B$5<>"",C19,"") | C20: =IF($B$5<>"",B20*(1+$B$5),"") | D20: =IF(C20="","",C20-B20)
A21: Oct | B21: =IF($B$5<>"",C20,"") | C21: =IF($B$5<>"",B21*(1+$B$5),"") | D21: =IF(C21="","",C21-B21)
A22: Nov | B22: =IF($B$5<>"",C21,"") | C22: =IF($B$5<>"",B22*(1+$B$5),"") | D22: =IF(C22="","",C22-B22)
A23: Dec | B23: =IF($B$5<>"",C22,"") | C23: =IF($B$5<>"",B23*(1+$B$5),"") | D23: =IF(C23="","",C23-B23)
A24: TOTAL | B24: =B12 | C24: =SUM(C12:C23) | D24: =SUM(D12:D23)
A26: Projected Year-End Revenue: | D26: =C24
A27: Total Growth over Baseline: | D27: =D24
A44: Scenario Comparison
A45: Growth Rate | B45: Projected Year-End Revenue | C45: vs Baseline
A46: 0.03 | B46: → Type in B5 →
A47: 0.05 | B47: → Type in B5 →
A48: 0.08 | B48: → Type in B5 →
A49: 0.1 | B49: → Type in B5 →
A51: Tip: Select a growth rate from the Quick Presets dropdown, copy it to cell B5, and the projection updates instantly.

Sheet Quaterly View
A3: Row Labels | B3: Sum of Revenue
A4: Q1 | B4: 383000
A5: Q2 | B5: 487000
A6: Q3 | B6: 546000
A7: Q4 | B7: 663000
A8: Grand Total | B8: 2079000
